package Schildt.part_10_Exceptions.p5;

class ThrowDemo {
    static void demoproc() {
        try {
            throw new NullPointerException("демонстрация");
        } catch (NullPointerException e) {
            System.out.println("Перехвачено внутри demoproc().");
            throw e;
        }
    }

    public static void main(String[] args) {
        try {
            demoproc();
        } catch (NullPointerException e) {
            System.out.println("Повторно перехвачено: " + e);
        }
    }
}
